# _Errors, Exceptions and Assertions_

Hasta ahora venimos viendo errores, excepciones y aserciones, pero nunca
hablamos detenidamente de ellos y qué diferencias podemos encontrar entre un
tipo y el otro. Vamos a por ello!

__Los errores o _errors_ son fallos provocados por el desarrollador... cuando
hacemos algo mal!__ 🤣 Por ejemplo, podría ser llamar a una función con argumentos
que no son válidos, buscar un elemento en una lista que no tiene dicho índice o
cosas por el estilo! En estos casos, __nuestro programa debería terminar de forma
inmediata__ ya que no es seguro el continuar una vez que se han producido estos errores.

__Las excepciones o _exceptions_ por el otro lado, muestran que algo inesperado
sucedió, algo fuera de nuestro control__. Sin embargo, pueden ser manejadas:
podríamos mostrarle un mensaje al usuario y luego recuperarnos y continuar con
la ejecución.

Finalmente, ya vimos lo que son __las _assertions_ o afirmaciones que nos permiten
chequear el código cuando estamos en _debug mode_ o tiempo de desarrollo,__ pero
lo hicimos en los comienzos de este curso. Ahora que ya las manejamos, vamos a
relacionarlas con los errores y las excepciones!

Es importante tener en cuenta que las _assertions_ en la lista de inicialización
se ejecutan en tiempo de compilación y se omiten en tiempo de ejecución en modo
release o cuando presentamos la app para el usuario. Por lo tanto, __no deben
utilizarse para validar entradas de usuario o comprobar condiciones que se
espera que se produzcan durante la ejecución normal del programa__. __Las
_assertions_  se utilizan para detectar errores de programación y asegurarse de
que las suposiciones del programador sobre el estado del programa sean correctas
en tiempo de ejecución.__

## Manejando errores en la _initializer list_

En Flutter, _framework_ que trabaja utilizando Dart como lenguaje, contamos con
una estructura basada en _Widgets_ y se dice que cada elemento en Flutter es un
_Widget_. Así por ejemplo, si queremos poner un botón en nuestra aplicación,
este botón será un _Widget_ y lo podríamos representar de forma muy simple con
una clase:

```dart
class FlutterButton {
  FlutterButton({required this.text});
  final String text;
}
```

Este botón por el momento no podría hacer nada ya que solo recibe el texto que
va a mostrar. Pero qué impediría que le pasemos cuando lo construyamos a este
botón, un `String` vacía?

```dart
void main() {
  final button = FlutterButton(text: '');
  print(button.text);
}
```

Absolutamente nada! Podríamos crear un test entonces, para cerciorarnos de que
si le pasamos un `String` vacía, nuestro constructor va a lanzar una excepción y
si le pasamos una `String` con caracteres, va a retornar normalmente:

```dart
void main() {
  group('Given a FlutterButton', () {
    test('When created with an empty text, Then should throw AssertionError', () {
      expect(() => FlutterButton(text: ''), throwsA(isA<AssertionError>()));
    });

    test('When created with text not empty, should return normally', () {
      expect(() => FlutterButton(text: 'Hello, world!'), returnsNormally);
    });
  });
}
```

Podemos observar varias cosas en nuestros tests:

### Funciones anónimas o referencias a función

- Utilizamos una función anónima como primer argumento en el `expect`:

Ustedes recuerdan que el método `expect` básicamente compara dos argumentos.
Bien, para poder chequear un error lanzado por una _assertion_,
utilizamos `throwsA` o 'lanzar un' en español. Este método recibe una función
que luego será ejecutada durante nuestro test. En el caso presente, dicha
función es `isA<AssertionError>()` que corrobora el tipo de error que va a estar
siendo lanzado por nuestra _assertion_. De esta forma, `throwsA` encapsula a
`isA<AssertionError>()` para ser ejecutada en el `expect`.

Venimos bien hasta ahí? Perfecto. Seguimos!

En el segundo argumento tenemos esta función que lanzará otra
función. En nuestro primer argumento debiéramos tener algo similar y así poder
compararlo: necesitamos entonces una función que lance otra función.

Tenemos ya una función que es la encargada de construir nuestro `FlutterButton`,
el constructor de dicha clase. Nos faltaría entonces una función que dispare
esta función constructora. Para ello, __utilizamos una función anónima que sirve
para encapsular la creación de la instancia de `FlutterButton`__ y así poder
comparar esta con aquella otra función.

Si se les complicó, vuelvan a leerlo detenidamente porque es medio enrevesado! 🤣

- Utilizamos `returnsNormally`

Parecido al caso anterior, solo que este `returnsNormally` es un `matcher` que
machea una llamada a una función cuando no produce ninguna excepción. Por eso,
el valor del primer argumento tiene nuevamente que ser una función anónima.

En ambos casos, __la función anónima es una referencia a una función ya que se va
a ejecutar luego dentro del `expect` así como lo hará el segundo término del
mismo, pudiendo ambos finalmente compararse.__

Ya que entendimos como nuestros tests están construidos, cómo lo implementamos?
Vamos a utilizar las _assertions_ dentro del constructor, en la _initializer
list_.

En cuanto a la ubicación de las _assertions_ en una inicialización de lista, se
recomienda colocarlas al principio, inmediatamente después de los `:`, antes de
cualquier otra expresión. Esto es porque las _initializer list_ se evalúan de
izquierda a derecha, y si hay una expresión inválida en la lista, la excepción
que se genera puede no estar relacionada con la expresión incorrecta. __Colocar
las _assertions_ al principio de la lista ayuda a identificar rápidamente
cualquier problema en los argumentos de entrada.__

```dart
class FlutterButton {
  FlutterButton({required this.text})
      : assert(text.isNotEmpty, 'Text can\'t be empty');
  final String text;
}
```

Ahora sí, si corremos los tests habiendo implementado la clase de esta manera,
vamos a estar seguros de que nuestro botón se va a construir de forma correcta.

Haciendo lo anterior, no evitamos un error ya que nada podría haber sucedido si
nuestro botón no muestra un texto en él; simplemente el usuario no vería nada.
Sin embargo, si se tratara de otro contexto podría haberse producido un fallo a
raíz de que no hicimos nuestros chequeos necesarios.

Posiblemente este no sea el ejemplo más preciso pero creo sirve a los fines de
que entiendan el funcionamiento de las _assertions_ en las listas de
inicialización y cómo adelantarnos escribiendo código defensivo.

## Try and catch

Si nosotros en el ejemplo anterior corríamos nuestra aplicación creando uno de
nuestros botones pero lo hacíamos con un texto vacío, ésta se detenía
completamente, no pudiendo completar la línea siguiente a la creación de dicho
botón, porque lanzaba una excepción que no controlábamos:

```dart
void main() {
  final button = FlutterButton(text: '');
  print('😋 Never gets here');
}
```

```shell
Unhandled exception:
'file:///Users/maurodibert/Development/dream_teamers/dream_teamers_courses/dart_sp/13.Async/general.dart': Failed assertion: line 4 pos 15: 'text.isNotEmpty': Text can't be empty
general.dart:4
#0      _AssertionError._doThrowNew (dart:core-patch/errors_patch.dart:51:61)
#1      _AssertionError._throwNew (dart:core-patch/errors_patch.dart:40:5)
#2      new FlutterButton
general.dart:4
#3      main
general.dart:23
#4      _delayEntrypointInvocation.<anonymous closure> (dart:isolate-patch/isolate_patch.dart:297:19)
#5      _RawReceivePortImpl._handleMessage (dart:isolate-patch/isolate_patch.dart:192:12)

Exited (255)
```

Cómo podemos controlarla? Utilizando _try_ (probar) y _catch_ (agarrar).
Básicamente este método nos permite intentar ejecutar código y, si sucediera
algún fallo en dicha ejecución, 'agarrarlo' o encapsularlo dentro de una
variable para que nosotros podamos hacer algo con él. Observemos:

```dart
void main() {
  try {
    final button = FlutterButton(text: '');
    // Si funciona
    // podríamos utilizar ese botón aquí
  } catch (e) {
    // (e es la variable que representa el error)
    // Si no funciona,
    // podemos imprimir el error
    print(e);
  }
  print('🚀 Now, gets here!');
}
```

Lo que hicimos fue abrir un bloque para el intento dentro de `try {}` y luego
otro para el manejo del error en `catch (e)`, siendo como se ve en el ejemplo,
`e` la variable que almacena el error.

Esto es lo que van a poder observar si lo ejecutan:

```shell
'file:///Users/maurodibert/Development/dream_teamers/dream_teamers_courses/dart_sp/13.Async/general.dart': Failed assertion: line 4 pos 15: 'text.isNotEmpty': Text can't be empty
general.dart:4
🚀 Now, gets here!

Exited
```

## Throw

Prueben el siguiente código con los tests con los que ya contaban:

```dart
class FlutterButton {
  FlutterButton({
    required this.text,
  }) {
    if (text.isEmpty) {
      throw AssertionError('Text can\'t be empty');
    }
  }

  final String text;
}
```

Tuvieron algún error? Esto exactamente lo que hace una _assertion_: 'lanza' una
excepción que luego vamos a poder tratar, solo que lo hace de forma más
suscinta.

__La _keyword_ `throw` lo que hace es simplemente lanzar algo y la
podemos utilizar en combinación con excepciones en cualquier momento para
prevenir un posible error. Cuando digo prevenir me refiero a que nos permite
utilizar `try {} catch(e) {}` para encapsular el error y mostrarle algo adecuado
al usuario.__

## 💪 Completando el botón

Un botón no sería exactamente un botón si no hiciera algo al ser apretado verdad?

__Requirement__: Sumarle al botón creado un parámetro llamado `onPressed` que
represente a una función. Dicha función puede ser nula ya que es una práctica
común el deshabilitar un botón al pasársele una `onPressed` nula pero no puede
recibir una función anónima vacía: `() {}`. Escriban los tests respectivos.

__Hint__: mmm... ya están a la altura de no recibir ninguno! A investigar!

---

__💀 Solución__:

```dart
import 'package:test/test.dart';

void main() {
  group('Given a FlutterButton', () {
    test('When created with an empty text, Then should throw AssertionError',
        () {
      expect(() => FlutterButton(text: ''), throwsA(isA<AssertionError>()));
    });

    test('When created with text not empty, should return normally', () {
      expect(() => FlutterButton(text: 'Hello, world!'), returnsNormally);
    });

    test(
        'When created with an empty onPressed, Then should throw AssertionError',
        () {
      expect(() => FlutterButton(text: 'Hello, world!', onPressed: () {}),
          throwsA(isA<AssertionError>()));
    });

    test(
        'When created with a onPressed that returns nothing, Then should throw AssertionError',
        () {
      expect(
          () => FlutterButton(
              text: 'Hello, world!',
              onPressed: () {
                // Do nothing
              }),
          throwsA(isA<AssertionError>()));
    });

    test(
        'When created with a onPressed that returns something, Then should return normally',
        () {
      expect(
          () => FlutterButton(
              text: 'Hello, world!', onPressed: () => print('test')),
          returnsNormally);
    });
  });
}

class FlutterButton {
  FlutterButton({
    required this.text,
    this.onPressed,
  }) {
    if (text.isEmpty) {
      throw AssertionError('Text can\'t be empty');
    }
    if (onPressed != null && onPressed.runtimeType == () {}.runtimeType) {
      throw AssertionError('onPressed can\'t be an empty function');
    }
  }

  final String text;
  final Function? onPressed;
}
```

__Explicación__:

`onPressed.runtimeType` devuelve el tipo de tiempo de ejecución de la función
`onPressed`. Por ejemplo, si `onPressed` es una función que retorna un `int`, su
tipo de tiempo de ejecución sería `() => int`. En cambio, si `onPressed` es
una función que no retorna nada (es decir, retorna `void`), su tipo de tiempo de
ejecución sería `() => void`.

Por otro lado, `() {}.runtimeType` se refiere al tipo de tiempo de ejecución de
una función anónima vacía. En otras palabras, es una función que no realiza
ninguna operación y no devuelve ningún valor, es decir, su tipo de tiempo de
ejecución es `() => Null`.

He aquí la prueba:

```dart
void main() {
  final voidFunction = () => print('test');
  print(() {}.runtimeType);
  print(voidFunction.runtimeType);
}
```

```shell
() => Null
() => void
Exited
```

## Try catch reforzado

Ya tenemos un código cada vez más completo pero nuestro botón no sería un super
botón si no le pasamos un color de fondo. Vamos a simular ese color con un enum:

```dart
enum Color {lightBlue, darkBlue, red, green, yellow, orange, purple, pink, brown, grey, black, white }
```

Y vamos a agregarlo a nuestra clase con un valor por defecto:

```dart
class FlutterButton {
  FlutterButton({
    required this.text,
    this.color = Color.lightBlue,
    this.onPressed,
  }) {
    if (text.isEmpty) {
      throw AssertionError('Text can\'t be empty');
    }
    if (onPressed != null && onPressed.runtimeType == () {}.runtimeType) {
      throw AssertionError('onPressed can\'t be an empty function');
    }
  }

  final String text;
  final Function? onPressed;
  final Color color;
}
```

Cuando definimos nuestros colores, agregamos la mayoría de los colores que
podríamos utilizar a lo largo de nuestra aplicación pero lo cierto es que alguno
de ellos son reservados: por ejemplo el color rojo sería mejor lo utilizáramos
en situaciones de error.

Vamos entonces a agregar una excepción específica cuando alguien le pase a este
botón el color rojo, una excepción que vamos a crear extendiendo la clase `Exceptions`:

```dart
class RedForErrorsException implements Exception {
  final String message;
  RedForErrorsException(this.message);
}

class FlutterButton {
  FlutterButton({
    required this.text,
    this.color = Color.lightBlue,
    this.onPressed,
  }) {
    if (text.isEmpty) {
      throw AssertionError('Text can\'t be empty');
    }
    if (onPressed != null && onPressed.runtimeType == () {}.runtimeType) {
      throw AssertionError('onPressed can\'t be an empty function');
    }
    if (color == Color.red) {
      throw RedForErrorsException('Color should be red just for errors');
    }
  }

  final String text;
  final Function? onPressed;
}
```

### On

Entonces, al momento de utilizar este botón podemos hacer algo específicamente
cuando la excepción sea del tipo RedForErrorsException, utilizando la palabra
`on`:

```dart
void main() {
  try {
    final button = FlutterButton(text: 'Send', color: Color.red);
    // Hacer algo aquí con el super botón
  } on RedForErrorsException catch (e) {
    print('☢️ This is a RedForErrorsException');
    print(e.message);
  } catch (e) {
    print(e);
  }
  print('🚀 Now, gets here!');
}
```

Si no necesitáramos de sus parámetros, podríamos omitir la palabra `catch`:

```dart
void main() {
  try {
    final button = FlutterButton(text: 'Send', color: Color.red);
    // Hacer algo aquí con el super botón
  } on RedForErrorsException { // 👁️
    print('☢️ This is a RedForErrorsException');
  } catch (e) {
    print(e);
  }
  print('🚀 Now, gets here!');
}
```

### Stack trace

Ya lo vimos pero lo vamos a recordar: El _stack trace_ es una lista de llamadas a
funciones activas en un punto particular de la ejecución del programa. Es decir,
cuando ocurre un error o una excepción en el código, el _stack trace_ muestra la
secuencia de llamadas a funciones que llevaron a ese punto del código. Se
utiliza comúnmente para depurar errores en el código y para entender mejor cómo
se comporta el programa en tiempo de ejecución ya que muestra la ubicación
exacta del error, lo que nos puede ayudar a identificar y corregir el problema.

Dentro de cada `catch`, el segundo parámetro, nos permite obtenerlo y
utilizarlo:

```dart
void main() {
  try {
    final button = FlutterButton(text: 'Send', color: Color.red);
    // Hacer algo aquí con el super botón
  } on RedForErrorsException catch (e, stackTrace) {
    // 👁️
    print(stackTrace);
    print('☢️ This is a RedForErrorsException');
    print(e.message);
  } catch (e) {
    print(e);
  }
  print('🚀 Now, gets here!');
}
```

```shell
#0      new FlutterButton
general.dart:14
#1      main
general.dart:85
#2      _delayEntrypointInvocation.<anonymous closure> (dart:isolate-patch/isolate_patch.dart:297:19)
#3      _RawReceivePortImpl._handleMessage (dart:isolate-patch/isolate_patch.dart:192:12)

☢️ This is a RedForErrorsException
Color should be red just for errors
🚀 Now, gets here!

Exited
```

### Finally

Podemos seguir sumando estadíos a nuestro `try {} catch(e,s) {}` y es el
`finally`, que nos permite hacer lo que queramos una vez que ya sucedió el `try`
y cada instancia de `catch` que queramos:

```dart
void main() {
  try {
    final button = FlutterButton(text: 'Send', color: Color.red);
    // Hacer algo aquí con el super botón
  } on RedForErrorsException catch (e, stackTrace) {
    print(stackTrace);
    print('☢️ This is a RedForErrorsException');
    print(e.message);
  } catch (e) {
    print(e);
  } finally {
    print('🎬 Finally');
  }
  print('🚀 Now, gets here!');
}
```

```shell
#0      new FlutterButton
general.dart:14
#1      main
general.dart:85
#2      _delayEntrypointInvocation.<anonymous closure> (dart:isolate-patch/isolate_patch.dart:297:19)
#3      _RawReceivePortImpl._handleMessage (dart:isolate-patch/isolate_patch.dart:192:12)

☢️ This is a RedForErrorsException
Color should be red just for errors
🎬 Finally
🚀 Now, gets here!

Exited
```

### Rethrow

Supongamos que este código que estamos escribiendo está metido mucho más adentro
de nuestro `main`. Podríamos hacer algo con la excepción `RedForErrorsException`
y luego volver a lanzarla para que otra capa de nuestro programa la maneje de
forma diferente; lo hacemos utilizando la _keyword_ `rethrow`:

```dart
void main() {
  try {
    final button = FlutterButton(text: 'Send', color: Color.red);
    // Hacer algo aquí con el super botón
  } on RedForErrorsException catch (e, stackTrace) {
    print(stackTrace);
    print('☢️ This is a RedForErrorsException');
    print(e.message);
    rethrow;
  } catch (e) {
    print(e);
  } finally {
    print('🎬 Finally');
  }
  print('🚀 Now, gets here!');
}
```

```shell
#0      new FlutterButton
general.dart:14
#1      main
general.dart:85
#2      _delayEntrypointInvocation.<anonymous closure> (dart:isolate-patch/isolate_patch.dart:297:19)
#3      _RawReceivePortImpl._handleMessage (dart:isolate-patch/isolate_patch.dart:192:12)

☢️ This is a RedForErrorsException
Color should be red just for errors
🎬 Finally

Unhandled exception:
Instance of 'RedForErrorsException'
#0      new FlutterButton
general.dart:14
#1      main
general.dart:85
#2      _delayEntrypointInvocation.<anonymous closure> (dart:isolate-patch/isolate_patch.dart:297:19)
#3      _RawReceivePortImpl._handleMessage (dart:isolate-patch/isolate_patch.dart:192:12)

Exited (255)
```

Allí podemos ver como la excepción vuelve a ser lanzada una vez pasado todo el
proceso!

## 💪 Creando función de creación de botón

Nuevamente, recuerden que esto es solo a los fines de la práctica ya que en
Flutter van a ver que no es una buena práctica el crear _widgets_ desde
funciones.

__Requirement__: Encapsular todo el `try / catch` anterior en una función y
crear otro `try / catch` que llame al anterior pero en este último, manejar la
excepción que relanzamos en el primero.

---

__💀 Solución__:

```dart

void main() {
  try {
    createButton();
  } catch (e) {
    print('🧘🏻 I manage excecptions by meditation');
    print(e);
  }
  print('🚀 Now, gets here!');
}

void createButton() {
  try {
    final button = FlutterButton(text: 'Send', color: Color.red);
    // Hacer algo aquí con el super botón
  } on RedForErrorsException catch (e, stackTrace) {
    print(stackTrace);
    print('☢️ This is a RedForErrorsException');
    print(e.message);
    rethrow;
  } catch (e) {
    print(e);
  } finally {
    print('🎬 Finally');
  }
}
```

## More exceptions

Quiero terminar este artículo diciéndoles que si escriben `throw Exception` van
a poder seleccionar entre una larga lista de excepciones listas para utilizarse.
Sin embargo, al iniciar cualquier aplicación, sería una buena práctica que
definan qué tipo de excepciones podrían tener y ordenarlas en un archivo
destinado específicamente a ello.
